Workbook

Sheet Portada - Indice
C2: THE KRAFT HEINZ COMPANY (KHC)
C3: Modelo Financiero Proyectado — 5 Años
C6: INFORMACIÓN DEL MODELO
C8: Autor: | D8: Santucci Andreas
C9: Fecha de Creación: | D9: 46143
C10: Última Actualización: | D10: 46160
C11: Fuente de Datos: | D11: Último 10-K de la SEC (FY 2024)
C12: Ticker: | D12: KHC (NASDAQ)
C13: Moneda: | D13: USD (en millones)
C14: Versión: | D14: v1.0
C16: ESTADO DEL MODELO
C18: Cuadre Balance General: | D18: {=IF(MAX(ABS(Modelo!G91:K91))<10,"✔ OK","⚠ Revisar (max "&TEXT(MAX(ABS(Modelo!G91:K91)),"$#,##0")&")")} -> ✔ OK
C19: Cuadre Estado de Resultados: | D19: =IF(AND(Modelo!F17<>"",Modelo!F22=Modelo!F17),"✔ OK","⚠ Revisar") -> ✔ OK
C20: Cuadre Flujo de Caja: | D20: =IF(ROUND(Modelo!K44,0)=ROUND(Modelo!K51,0),"✔ OK","⚠ Revisar ("&TEXT(Modelo!K44-Modelo!K51,"$#,##0")&")") -> ✔ OK
C24: ÍNDICE DE CONTENIDOS
B26: 1 | C26: =HYPERLINK("#'Supuestos'!A1","Supuestos") -> Supuestos | D26: Ingresos por segmento, márgenes, drivers de balance, otros supuestos y parámetros de valuación terminal (WACC, g, múltiplo de salida)
B28: 2 | C28: =HYPERLINK("#'Modelo'!A1","Modelo") -> Modelo | D28: Estado de Resultados, Flujo de Caja y Balance General proyectados (2022–2029E) con control de cuadre
B30: 3 | C30: =HYPERLINK("#'Insights'!A1","Insights") -> Insights | D30: KPIs: crecimiento y rentabilidad, generación de caja, eficiencia y solvencia, retorno al accionista, análisis de riesgo
B32: 4 | C32: =HYPERLINK("#'Dashboard - Resultados'!A1","Dashboard - Resultados") -> Dashboard - Resultados | D32: Tarjetas ejecutivas y gráficos clave: ventas, márgenes, FCF, apalancamiento y retorno al accionista
C36: CONVENCIONES DE COLOR
C38: ■ Azul | D38: Datos duros / Inputs manuales (hardcoded)
C39: ■ Negro | D39: Fórmulas y cálculos dentro de la misma hoja
C40: ■ Verde | D40: Referencias cruzadas a otras hojas del modelo
C41: ■ Rojo | D41: Links externos a otros archivos
C44: Confidencial — Solo para uso interno

Sheet Supuestos
A1: =HYPERLINK("#'Portada - Indice'!A1","← Volver a Portada") -> ← Volver a Portada
B2: SUPUESTOS DEL MODELO | D2: 2022 | E2: 2023 | F2: 2024 | G2: 2025E | H2: 2026E | I2: 2027E | J2: 2028E | K2: 2029E
B4: 1. INGRESOS POR SEGMENTO
B6: Ventas Netas por Segmento | C6: ($mm)
B7: Norteamérica | C7: $mm | D7: 20340 | E7: 20126 | F7: 19543 | G7: =F7*(1+G13) -> 19347.57 | H7: =G7*(1+H13) -> 19444.308 | I7: =H7*(1+I13) -> 19638.751 | J7: =I7*(1+J13) -> 19835.138 | K7: =J7*(1+K13) -> 20132.666
B8: Mercados Desarrollados Internacionales | C8: $mm | D8: 3401 | E8: 3623 | F8: 3535 | G8: =F8*(1+G14) -> 3570.35 | H8: =G8*(1+H14) -> 3623.9052 | I8: =H8*(1+I14) -> 3696.3834 | J8: =I8*(1+J14) -> 3770.311 | K8: =J8*(1+K14) -> 3845.7172
B9: Mercados Emergentes | C9: $mm | D9: 2744 | E9: 2891 | F9: 2768 | G9: =F9*(1+G15) -> 2851.04 | H9: =G9*(1+H15) -> 2950.8264 | I9: =H9*(1+I15) -> 3068.8595 | J9: =I9*(1+J15) -> 3191.6138 | K9: =J9*(1+K15) -> 3319.2784
B10: Ventas Netas Totales | C10: $mm | D10: =SUM(D7:D9) -> 26485 | E10: =SUM(E7:E9) -> 26640 | F10: =SUM(F7:F9) -> 25846 | G10: =SUM(G7:G9) -> 25768.96 | H10: =SUM(H7:H9) -> 26019.039 | I10: =SUM(I7:I9) -> 26403.994 | J10: =SUM(J7:J9) -> 26797.063 | K10: =SUM(K7:K9) -> 27297.661
B12: Crecimiento por Segmento | C12: (%)
B13: Norteamérica | C13: % | E13: =E7/D7-1 -> -0.010521141 | F13: =F7/E7-1 -> -0.028967505 | G13: -0.01 | H13: 0.005 | I13: 0.01 | J13: 0.01 | K13: 0.015
B14: Mercados Desarrollados Internacionales | C14: % | E14: =E8/D8-1 -> 0.065274919 | F14: =F8/E8-1 -> -0.024289263 | G14: 0.01 | H14: 0.015 | I14: 0.02 | J14: 0.02 | K14: 0.02
B15: Mercados Emergentes | C15: % | E15: =E9/D9-1 -> 0.053571429 | F15: =F9/E9-1 -> -0.042545832 | G15: 0.03 | H15: 0.035 | I15: 0.04 | J15: 0.04 | K15: 0.04
B16: Crecimiento Total Ventas Netas | C16: % | E16: =E10/D10-1 -> 0.0058523693 | F16: =F10/E10-1 -> -0.029804805 | G16: =G10/F10-1 -> -0.002980732 | H16: =H10/G10-1 -> 0.0097046796 | I16: =I10/H10-1 -> 0.014795098 | J16: =J10/I10-1 -> 0.014886746 | K16: =(K10-J10)/J10 -> 0.018681071
B18: 2. MÁRGENES Y GASTOS
B20: Margen Bruto | C20: % | D20: =8122/D10 -> 0.30666415 | E20: =8926/E10 -> 0.33506006 | F20: =8968/F10 -> 0.34697826 | G20: 0.348 | H20: 0.35 | I20: 0.352 | J20: 0.355 | K20: 0.357
B21: SG&A (ex impairments) / Ventas | C21: % | D21: =3575/D10 -> 0.13498207 | E21: =3692/E10 -> 0.13858859 | F21: =3616/F10 -> 0.13990559 | G21: 0.139 | H21: 0.138 | I21: 0.137 | J21: 0.136 | K21: 0.135
B22: D&A | C22: $mm | D22: 933 | E22: 961 | F22: 948 | G22: =G23*F43 -> 951.216 | H22: =H23*G43 -> 961.79514 | I22: =I23*H43 -> 972.29768 | J22: =J23*I43 -> 983.45133 | K22: =K23*J43 -> 995.21268
B23: D&A / PP&E (inicio período) | C23: % | D23: =D22/D43 -> 0.13122363 | E23: =E22/D43 -> 0.13516174 | F23: =F22/E43 -> 0.13310868 | G23: 0.133 | H23: 0.133 | I23: 0.133 | J23: 0.133 | K23: 0.133
B24: Gasto por Intereses | C24: $mm | D24: 921 | E24: 912 | F24: 912 | G24: 900 | H24: 885 | I24: 870 | J24: 855 | K24: 840
B25: Otro Gasto/(Ingreso) | C25: $mm | D25: 253 | E25: -27 | F25: 85 | G25: 0 | H25: 0 | I25: 0 | J25: 0 | K25: 0
B26: Tasa Impositiva Efectiva | C26: % | D26: =598/2966 -> 0.20161834 | E26: =787/3633 -> 0.21662538 | F26: N/A | G26: 0.22 | H26: 0.22 | I26: 0.22 | J26: 0.22 | K26: 0.22
B27: Impairments (Goodwill + Intangibles) | C27: $mm | D27: =444+469 -> 913 | E27: =510+152 -> 662 | F27: =1638+2031 -> 3669 | G27: 0 | H27: 0 | I27: 0 | J27: 0 | K27: 0
B29: 3. DRIVERS DE BALANCE
B31: Cuentas por Cobrar (AR) | C31: $mm | E31: 2112 | F31: 2147 | G31: =G36/365*G10 -> 2139.1767 | H31: =H36/365*H10 -> 2138.5512 | I31: =I36/365*I10 -> 2170.1913 | J31: =J36/365*J10 -> 2202.4984 | K31: =K36/365*K10 -> 2243.6434
B32: Inventarios | C32: $mm | E32: 3614 | F32: 3376 | G32: =G37/365*(G10*(1-G20)) -> 3360.2724 | H32: =H37/365*(H10*(1-H20)) -> 3336.1399 | I32: =I37/365*(I10*(1-I20)) -> 3328.2053 | J32: =J37/365*(J10*(1-J20)) -> 3314.76 | K32: =K37/365*(K10*(1-K20)) -> 3366.213
B33: Cuentas por Pagar (AP) | C33: $mm | E33: 4627 | F33: 4188 | G33: =G38/365*(G10*(1-G20)) -> 4142.8016 | H33: =H38/365*(H10*(1-H20)) -> 4123.8395 | I33: =I38/365*(I10*(1-I20)) -> 4125.0996 | J33: =J38/365*(J10*(1-J20)) -> 4119.7732 | K33: =K38/365*(K10*(1-K20)) -> 4183.7218
B35: Capital de Trabajo
B36: DSO (Días de Cobro) | C36: días | E36: =E31/E10*365 -> 28.936937 | F36: =F31/F10*365 -> 30.320166 | G36: 30.3 | H36: 30 | I36: 30 | J36: 30 | K36: 30
B37: DIO (Días de Inventario) | C37: días | E37: =E32/(E10*(1-E20))*365 -> 74.467088 | F37: =F32/(F10*(1-F20))*365 -> 73.00865 | G37: 73 | H37: 72 | I37: 71 | J37: 70 | K37: 70
B38: DPO (Días de Pago) | C38: días | E38: =E33/(E10*(1-E20))*365 -> 95.340126 | F38: =F33/(F10*(1-F20))*365 -> 90.568788 | G38: 90 | H38: 89 | I38: 88 | J38: 87 | K38: 87
B40: Inversiones (Capex & PP&E)
B41: Capex | C41: $mm | D41: 916 | E41: 1013 | F41: 1024 | G41: =G42*G10 -> 1030.7584 | H41: =H42*H10 -> 1040.7616 | I41: =I42*I10 -> 1056.1597 | J41: =J42*J10 -> 1071.8825 | K41: =K42*K10 -> 1091.9064
B42: Capex / Ventas | C42: % | D42: =D41/D10 -> 0.034585614 | E42: =E41/E10 -> 0.038025526 | F42: =F41/F10 -> 0.039619283 | G42: 0.04 | H42: 0.04 | I42: 0.04 | J42: 0.04 | K42: 0.04
B43: PP&E Neto | C43: $mm | D43: 7110 | E43: 7122 | F43: 7152 | G43: =F43+G41-G22 -> 7231.5424 | H43: =G43+H41-H22 -> 7310.5088 | I43: =H43+I41-I22 -> 7394.3709 | J43: =I43+J41-J22 -> 7482.8021 | K43: =J43+K41-K22 -> 7579.4959
B44: Crédito Mercantil e Intangibles | C44: $mm | E44: 72907 | F44: 68772 | G44: =F44-G27 -> 68772 | H44: =G44-H27 -> 68772 | I44: =H44-I27 -> 68772 | J44: =I44-J27 -> 68772 | K44: =J44-K27 -> 68772
B45: Caja y Equivalentes | C45: $mm | E45: 1400 | F45: 1334 | G45: =Modelo!G44 -> 1651.7175 | H45: =Modelo!H44 -> 2090.5552 | I45: =Modelo!I44 -> 2615.2052 | J45: =Modelo!J44 -> 3276.0681 | K45: =Modelo!K44 -> 4066.1221
B46: Otros Activos No Corrientes | C46: $mm | E46: 2381 | F46: 4708 | G46: =F46 -> 4708 | H46: =G46 -> 4708 | I46: =H46 -> 4708 | J46: =I46 -> 4708 | K46: =J46 -> 4708
B48: Porción Corriente Deuda LP | C48: $mm | E48: 638 | F48: 654 | G48: 650 | H48: 650 | I48: 650 | J48: 650 | K48: 650
B49: Otros Pasivos No Corrientes | C49: $mm | E49: 2985 | F49: 2815 | G49: =F49 -> 2815 | H49: =G49 -> 2815 | I49: =H49 -> 2815 | J49: =I49 -> 2815 | K49: =J49 -> 2815
B51: Patrimonio
...

Sheet Modelo
A1: ← Volver a Portada
B2: MODELO FINANCIERO | D2: 2022 | E2: 2023 | F2: 2024 | G2: 2025E | H2: 2026E | I2: 2027E | J2: 2028E | K2: 2029E
B4: ESTADO DE RESULTADOS | C4: ($mm)
B6: Ventas Netas Totales | D6: =Supuestos!D10 -> 26485 | E6: =Supuestos!E10 -> 26640 | F6: =Supuestos!F10 -> 25846 | G6: =Supuestos!G10 -> 25768.96 | H6: =Supuestos!H10 -> 26019.039 | I6: =Supuestos!I10 -> 26403.994 | J6: =Supuestos!J10 -> 26797.063 | K6: =Supuestos!K10 -> 27297.661
B7: Costo de Ventas (COGS) | D7: =-D6*(1-Supuestos!D20) -> -18363 | E7: =-E6*(1-Supuestos!E20) -> -17714 | F7: =-F6*(1-Supuestos!F20) -> -16878 | G7: =-G6*(1-Supuestos!G20) -> -16801.362 | H7: =-H6*(1-Supuestos!H20) -> -16912.376 | I7: =-I6*(1-Supuestos!I20) -> -17109.788 | J7: =-J6*(1-Supuestos!J20) -> -17284.106 | K7: =-K6*(1-Supuestos!K20) -> -17552.396
B8: Utilidad Bruta | D8: =D6+D7 -> 8122 | E8: =E6+E7 -> 8926 | F8: =F6+F7 -> 8968 | G8: =G6+G7 -> 8967.5981 | H8: =H6+H7 -> 9106.6638 | I8: =I6+I7 -> 9294.2058 | J8: =J6+J7 -> 9512.9575 | K8: =K6+K7 -> 9745.265
B9: Gastos de Venta y Administración (ex deterioros) | D9: =-D6*Supuestos!D21 -> -3575 | E9: =-E6*Supuestos!E21 -> -3692 | F9: =-F6*Supuestos!F21 -> -3616 | G9: =-G6*Supuestos!G21 -> -3581.8854 | H9: =-H6*Supuestos!H21 -> -3590.6275 | I9: =-I6*Supuestos!I21 -> -3617.3471 | J9: =-J6*Supuestos!J21 -> -3644.4006 | K9: =-K6*Supuestos!K21 -> -3685.1843
B10: Depreciación y Amortización | D10: =-Supuestos!D22 -> -933 | E10: =-Supuestos!E22 -> -961 | F10: =-Supuestos!F22 -> -948 | G10: =-Supuestos!G22 -> -951.216 | H10: =-Supuestos!H22 -> -961.79514 | I10: =-Supuestos!I22 -> -972.29768 | J10: =-Supuestos!J22 -> -983.45133 | K10: =-Supuestos!K22 -> -995.21268
B11: Deterioros (Crédito Mercantil e Intangibles) | D11: =-Supuestos!D27 -> -913 | E11: =-Supuestos!E27 -> -662 | F11: =-Supuestos!F27 -> -3669 | G11: =-Supuestos!G27 -> 0 | H11: =-Supuestos!H27 -> 0 | I11: =-Supuestos!I27 -> 0 | J11: =-Supuestos!J27 -> 0 | K11: =-Supuestos!K27 -> 0
B12: Utilidad Operativa (EBIT) | D12: =D8+D9+D10+D11 -> 2701 | E12: =E8+E9+E10+E11 -> 3611 | F12: =F8+F9+F10+F11 -> 735 | G12: =G8+G9+G10+G11 -> 4434.4966 | H12: =H8+H9+H10+H11 -> 4554.2412 | I12: =I8+I9+I10+I11 -> 4704.561 | J12: =J8+J9+J10+J11 -> 4885.1055 | K12: =K8+K9+K10+K11 -> 5064.8681
B13: Gasto por Intereses | D13: =-Supuestos!D24 -> -921 | E13: =-Supuestos!E24 -> -912 | F13: =-Supuestos!F24 -> -912 | G13: =-Supuestos!G24 -> -900 | H13: =-Supuestos!H24 -> -885 | I13: =-Supuestos!I24 -> -870 | J13: =-Supuestos!J24 -> -855 | K13: =-Supuestos!K24 -> -840
B14: Otro Gasto / (Ingreso) | D14: =-Supuestos!D25 -> -253 | E14: =-Supuestos!E25 -> 27 | F14: =-Supuestos!F25 -> -85 | G14: =-Supuestos!G25 -> 0 | H14: =-Supuestos!H25 -> 0 | I14: =-Supuestos!I25 -> 0 | J14: =-Supuestos!J25 -> 0 | K14: =-Supuestos!K25 -> 0
B15: Utilidad antes de Impuestos (EBT) | D15: =D12+D13+D14 -> 1527 | E15: =E12+E13+E14 -> 2726 | F15: =F12+F13+F14 -> -262 | G15: =G12+G13+G14 -> 3534.4966 | H15: =H12+H13+H14 -> 3669.2412 | I15: =I12+I13+I14 -> 3834.561 | J15: =J12+J13+J14 -> 4030.1055 | K15: =K12+K13+K14 -> 4224.8681
B16: Impuesto a las Ganancias | D16: =-D15*Supuestos!D26 -> -307.87121 | E16: =-E15*Supuestos!E26 -> -590.52078 | F16: 1561 | G16: =-G15*Supuestos!G26 -> -777.58926 | H16: =-H15*Supuestos!H26 -> -807.23307 | I16: =-I15*Supuestos!I26 -> -843.60342 | J16: =-J15*Supuestos!J26 -> -886.62322 | K16: =-K15*Supuestos!K26 -> -929.47098
B17: Utilidad Neta | D17: =D15+D16 -> 1219.1288 | E17: =E15+E16 -> 2135.4792 | F17: =F15+F16 -> 1299 | G17: =G15+G16 -> 2756.9074 | H17: =H15+H16 -> 2862.0082 | I17: =I15+I16 -> 2990.9576 | J17: =J15+J16 -> 3143.4823 | K17: =K15+K16 -> 3295.3971
B20: FLUJO DE CAJA | C20: ($mm)
B21: Actividades Operativas
B22: Utilidad Neta | D22: =D17 -> 1219.1288 | E22: =E17 -> 2135.4792 | F22: =F17 -> 1299 | G22: =G17 -> 2756.9074 | H22: =H17 -> 2862.0082 | I22: =I17 -> 2990.9576 | J22: =J17 -> 3143.4823 | K22: =K17 -> 3295.3971
B23: (+) Depreciación y Amortización | D23: =-D10 -> 933 | E23: =-E10 -> 961 | F23: =-F10 -> 948 | G23: =-G10 -> 951.216 | H23: =-H10 -> 961.79514 | I23: =-I10 -> 972.29768 | J23: =-J10 -> 983.45133 | K23: =-K10 -> 995.21268
B24: (+) Deterioros (no monetario) | D24: =-D11 -> 913 | E24: =-E11 -> 662 | F24: =-F11 -> 3669 | G24: =-G11 -> 0 | H24: =-H11 -> 0 | I24: =-I11 -> 0 | J24: =-J11 -> 0 | K24: =-K11 -> 0
B25: (+/-) Δ Impuestos Diferidos | F25: =Supuestos!F60-Supuestos!E60 -> -522 | G25: =Supuestos!G60-Supuestos!F60 -> -179 | H25: =Supuestos!H60-Supuestos!G60 -> -200 | I25: =Supuestos!I60-Supuestos!H60 -> -200 | J25: =Supuestos!J60-Supuestos!I60 -> -200 | K25: =Supuestos!K60-Supuestos!J60 -> -200
B26: (+/-) Δ Cuentas por Cobrar | F26: =-(Supuestos!F31-Supuestos!E31) -> -35 | G26: =-(Supuestos!G31-Supuestos!F31) -> 7.8233205 | H26: =-(Supuestos!H31-Supuestos!G31) -> 0.62548767 | I26: =-(Supuestos!I31-Supuestos!H31) -> -31.640074 | J26: =-(Supuestos!J31-Supuestos!I31) -> -32.307087 | K26: =-(Supuestos!K31-Supuestos!J31) -> -41.145029
B27: (+/-) Δ Inventarios | F27: =-(Supuestos!F32-Supuestos!E32) -> 238 | G27: =-(Supuestos!G32-Supuestos!F32) -> 15.727616 | H27: =-(Supuestos!H32-Supuestos!G32) -> 24.132525 | I27: =-(Supuestos!I32-Supuestos!H32) -> 7.9345332 | J27: =-(Supuestos!J32-Supuestos!I32) -> 13.445305 | K27: =-(Supuestos!K32-Supuestos!J32) -> -51.452933
B28: (+/-) Δ Cuentas por Pagar | F28: =Supuestos!F33-Supuestos!E33 -> -439 | G28: =Supuestos!G33-Supuestos!F33 -> -45.198431 | H28: =Supuestos!H33-Supuestos!G33 -> -18.962021 | I28: =Supuestos!I33-Supuestos!H33 -> 1.2600108 | J28: =Supuestos!J33-Supuestos!I33 -> -5.3263897 | K28: =Supuestos!K33-Supuestos!J33 -> 63.948645
B29: (+/-) Otras variaciones de capital de trabajo | F29: -1158 | G29: 0 | H29: 0 | I29: 0 | J29: 0 | K29: 0
B30: Flujo de Caja Operativo (CFO) | F30: =SUM(F22:F29) -> 4000 | G30: =SUM(G22:G29) -> 3507.4759 | H30: =SUM(H22:H29) -> 3629.5993 | I30: =SUM(I22:I29) -> 3740.8097 | J30: =SUM(J22:J29) -> 3902.7455 | K30: =SUM(K22:K29) -> 4061.9605
B32: Actividades de Inversión
B33: (-) Capex | D33: =-Supuestos!D41 -> -916 | E33: =-Supuestos!E41 -> -1013 | F33: =-Supuestos!F41 -> -1024 | G33: =-Supuestos!G41 -> -1030.7584 | H33: =-Supuestos!H41 -> -1040.7616 | I33: =-Supuestos!I41 -> -1056.1597 | J33: =-Supuestos!J41 -> -1071.8825 | K33: =-Supuestos!K41 -> -1091.9064
B34: Flujo de Caja de Inversión (CFI) | D34: =D33 -> -916 | E34: =E33 -> -1013 | F34: =SUM(F33:F33) -> -1024 | G34: =SUM(G33:G33) -> -1030.7584 | H34: =SUM(H33:H33) -> -1040.7616 | I34: =SUM(I33:I33) -> -1056.1597 | J34: =SUM(J33:J33) -> -1071.8825 | K34: =SUM(K33:K33) -> -1091.9064
B36: Actividades de Financiamiento
B37: (+/-) Δ Deuda LP | F37: =Supuestos!F59-Supuestos!E59 -> -179 | G37: =(Supuestos!G59+Supuestos!G48)-(Supuestos!F59+Supuestos!F48) -> -219 | H37: =(Supuestos!H59+Supuestos!H48)-(Supuestos!G59+Supuestos!G48) -> -200 | I37: =(Supuestos!I59+Supuestos!I48)-(Supuestos!H59+Supuestos!H48) -> -200 | J37: =(Supuestos!J59+Supuestos!J48)-(Supuestos!I59+Supuestos!I48) -> -200 | K37: =(Supuestos!K59+Supuestos!K48)-(Supuestos!J59+Supuestos!J48) -> -200
B38: (-) Dividendos Pagados | D38: =-Supuestos!D62 -> -1960 | E38: =-Supuestos!E62 -> -1965 | F38: =-Supuestos!F62 -> -1931 | G38: =-Supuestos!G62 -> -1940 | H38: =-Supuestos!H62 -> -1950 | I38: =-Supuestos!I62 -> -1960 | J38: =-Supuestos!J62 -> -1970 | K38: =-Supuestos!K62 -> -1980
B39: (-) Recompras de Acciones | F39: -932 | G39: 0 | H39: 0 | I39: 0 | J39: 0 | K39: 0
B40: Flujo de Caja de Financiamiento (CFF) | F40: =SUM(F37:F39) -> -3042 | G40: =SUM(G37:G39) -> -2159 | H40: =SUM(H37:H39) -> -2150 | I40: =SUM(I37:I39) -> -2160 | J40: =SUM(J37:J39) -> -2170 | K40: =SUM(K37:K39) -> -2180
B42: Variación Neta de Caja | F42: =F30+F34+F40 -> -66 | G42: =G30+G34+G40 -> 317.71749 | H42: =H30+H34+H40 -> 438.83771 | I42: =I30+I34+I40 -> 524.64996 | J42: =J30+J34+J40 -> 660.86294 | K42: =K30+K34+K40 -> 790.05403
B43: Caja Inicio del Período | F43: =E44 -> 1400 | G43: =Supuestos!F45 -> 1334 | H43: =G44 -> 1651.7175 | I43: =H44 -> 2090.5552 | J43: =I44 -> 2615.2052 | K43: =J44 -> 3276.0681
B44: Caja Fin del Período | E44: 1400 | F44: 1334 | G44: =G42+G43 -> 1651.7175 | H44: =H42+H43 -> 2090.5552 | I44: =I42+I43 -> 2615.2052 | J44: =J42+J43 -> 3276.0681 | K44: =K42+K43 -> 4066.1221
B47: BALANCE GENERAL | C47: ($mm)
B49: ACTIVOS
B50: Activos Corrientes
...

Sheet Insights
A1: =HYPERLINK("#'Portada - Indice'!A1","← Volver a Portada") -> ← Volver a Portada
B2: RESUMEN DE DATOS — KRAFT HEINZ (KHC)
B3: Métrica | C3: Unidad | D3: =Modelo!D2 -> 2022 | E3: =Modelo!E2 -> 2023 | F3: =Modelo!F2 -> 2024 | G3: =Modelo!G2 -> 2025E | H3: =Modelo!H2 -> 2026E | I3: =Modelo!I2 -> 2027E | J3: =Modelo!J2 -> 2028E | K3: =Modelo!K2 -> 2029E
B5: 1. CRECIMIENTO Y RENTABILIDAD
B7: Ventas Netas | C7: $mm | D7: =Modelo!D6 -> 26485 | E7: =Modelo!E6 -> 26640 | F7: =Modelo!F6 -> 25846 | G7: =Modelo!G6 -> 25768.96 | H7: =Modelo!H6 -> 26019.039 | I7: =Modelo!I6 -> 26403.994 | J7: =Modelo!J6 -> 26797.063 | K7: =Modelo!K6 -> 27297.661
B8: Crecimiento de Ventas | C8: % | D8: =IFERROR(Modelo!D6/Modelo!C6-1,"") | E8: =IFERROR(Modelo!E6/Modelo!D6-1,"") -> 0.0058523693 | F8: =IFERROR(Modelo!F6/Modelo!E6-1,"") -> -0.029804805 | G8: =IFERROR(Modelo!G6/Modelo!F6-1,"") -> -0.002980732 | H8: =IFERROR(Modelo!H6/Modelo!G6-1,"") -> 0.0097046796 | I8: =IFERROR(Modelo!I6/Modelo!H6-1,"") -> 0.014795098 | J8: =IFERROR(Modelo!J6/Modelo!I6-1,"") -> 0.014886746 | K8: =IFERROR(Modelo!K6/Modelo!J6-1,"") -> 0.018681071
B9: EBITDA | C9: $mm | D9: =Modelo!D12-Modelo!D10 -> 3634 | E9: =Modelo!E12-Modelo!E10 -> 4572 | F9: =Modelo!F12-Modelo!F10 -> 1683 | G9: =Modelo!G12-Modelo!G10 -> 5385.7126 | H9: =Modelo!H12-Modelo!H10 -> 5516.0364 | I9: =Modelo!I12-Modelo!I10 -> 5676.8587 | J9: =Modelo!J12-Modelo!J10 -> 5868.5569 | K9: =Modelo!K12-Modelo!K10 -> 6060.0808
B10: Margen EBITDA | C10: % | D10: =IFERROR((Modelo!D12-Modelo!D10)/Modelo!D6,"") -> 0.13720974 | E10: =IFERROR((Modelo!E12-Modelo!E10)/Modelo!E6,"") -> 0.17162162 | F10: =IFERROR((Modelo!F12-Modelo!F10)/Modelo!F6,"") -> 0.065116459 | G10: =IFERROR((Modelo!G12-Modelo!G10)/Modelo!G6,"") -> 0.209 | H10: =IFERROR((Modelo!H12-Modelo!H10)/Modelo!H6,"") -> 0.212 | I10: =IFERROR((Modelo!I12-Modelo!I10)/Modelo!I6,"") -> 0.215 | J10: =IFERROR((Modelo!J12-Modelo!J10)/Modelo!J6,"") -> 0.219 | K10: =IFERROR((Modelo!K12-Modelo!K10)/Modelo!K6,"") -> 0.222
B11: Utilidad Neta | C11: $mm | D11: =Modelo!D17 -> 1219.1288 | E11: =Modelo!E17 -> 2135.4792 | F11: =Modelo!F17 -> 1299 | G11: =Modelo!G17 -> 2756.9074 | H11: =Modelo!H17 -> 2862.0082 | I11: =Modelo!I17 -> 2990.9576 | J11: =Modelo!J17 -> 3143.4823 | K11: =Modelo!K17 -> 3295.3971
B12: Margen Neto | C12: % | D12: =IFERROR(Modelo!D17/Modelo!D6,"") -> 0.046030915 | E12: =IFERROR(Modelo!E17/Modelo!E6,"") -> 0.080160631 | F12: =IFERROR(Modelo!F17/Modelo!F6,"") -> 0.050259228 | G12: =IFERROR(Modelo!G17/Modelo!G6,"") -> 0.10698559 | H12: =IFERROR(Modelo!H17/Modelo!H6,"") -> 0.10999669 | I12: =IFERROR(Modelo!I17/Modelo!I6,"") -> 0.11327671 | J12: =IFERROR(Modelo!J17/Modelo!J6,"") -> 0.11730697 | K12: =IFERROR(Modelo!K17/Modelo!K6,"") -> 0.12072086
B14: 2. GENERACIÓN DE CAJA
B16: Flujo de Caja Libre | C16: $mm | D16: =IFERROR(Modelo!D30+Modelo!D33,"") -> -916 | E16: =IFERROR(Modelo!E30+Modelo!E33,"") -> -1013 | F16: =IFERROR(Modelo!F30+Modelo!F33,"") -> 2976 | G16: =IFERROR(Modelo!G30+Modelo!G33,"") -> 2476.7175 | H16: =IFERROR(Modelo!H30+Modelo!H33,"") -> 2588.8377 | I16: =IFERROR(Modelo!I30+Modelo!I33,"") -> 2684.65 | J16: =IFERROR(Modelo!J30+Modelo!J33,"") -> 2830.8629 | K16: =IFERROR(Modelo!K30+Modelo!K33,"") -> 2970.054
B17: Tasa de Conversión de FCF | C17: % | D17: =IFERROR((Modelo!D30+Modelo!D33)/(Modelo!D12-Modelo!D10),"") -> -0.25206384 | E17: =IFERROR((Modelo!E30+Modelo!E33)/(Modelo!E12-Modelo!E10),"") -> -0.22156605 | F17: =IFERROR((Modelo!F30+Modelo!F33)/(Modelo!F12-Modelo!F10),"") -> 1.7682709 | G17: =IFERROR((Modelo!G30+Modelo!G33)/(Modelo!G12-Modelo!G10),"") -> 0.45986811 | H17: =IFERROR((Modelo!H30+Modelo!H33)/(Modelo!H12-Modelo!H10),"") -> 0.46932934 | I17: =IFERROR((Modelo!I30+Modelo!I33)/(Modelo!I12-Modelo!I10),"") -> 0.47291119 | J17: =IFERROR((Modelo!J30+Modelo!J33)/(Modelo!J12-Modelo!J10),"") -> 0.48237804 | K17: =IFERROR((Modelo!K30+Modelo!K33)/(Modelo!K12-Modelo!K10),"") -> 0.49010139
B19: 3. EFICIENCIA Y SOLVENCIA
B21: ROIC | C21: % | D21: =IFERROR((Modelo!D12*(1-Supuestos!D26))/(Modelo!D73+Modelo!D68+Modelo!D86),"") | E21: =IFERROR((Modelo!E12*(1-Supuestos!E26))/(Modelo!E73+Modelo!E68+Modelo!E86),"") -> 0.040737421 | F21: =IFERROR((Modelo!F12*(1-Supuestos!F26))/(Modelo!F73+Modelo!F68+Modelo!F86),"") | G21: =IFERROR((Modelo!G12*(1-Supuestos!G26))/(Modelo!G73+Modelo!G68+Modelo!G86),"") -> 0.049564554 | H21: =IFERROR((Modelo!H12*(1-Supuestos!H26))/(Modelo!H73+Modelo!H68+Modelo!H86),"") -> 0.05038884 | I21: =IFERROR((Modelo!I12*(1-Supuestos!I26))/(Modelo!I73+Modelo!I68+Modelo!I86),"") -> 0.051445612 | J21: =IFERROR((Modelo!J12*(1-Supuestos!J26))/(Modelo!J73+Modelo!J68+Modelo!J86),"") -> 0.052700666 | K21: =IFERROR((Modelo!K12*(1-Supuestos!K26))/(Modelo!K73+Modelo!K68+Modelo!K86),"") -> 0.053809834
B22: Deuda Neta / EBITDA | C22: x | D22: =IFERROR((Modelo!D73+Modelo!D68-Modelo!D51)/(Modelo!D12-Modelo!D10),"") -> 0 | E22: =IFERROR((Modelo!E73+Modelo!E68-Modelo!E51)/(Modelo!E12-Modelo!E10),"") -> 4.0752406 | F22: =IFERROR((Modelo!F73+Modelo!F68-Modelo!F51)/(Modelo!F12-Modelo!F10),"") -> 11.013072 | G22: =IFERROR((Modelo!G73+Modelo!G68-Modelo!G51)/(Modelo!G12-Modelo!G10),"") -> 3.3418572 | H22: =IFERROR((Modelo!H73+Modelo!H68-Modelo!H51)/(Modelo!H12-Modelo!H10),"") -> 3.1470867 | I22: =IFERROR((Modelo!I73+Modelo!I68-Modelo!I51)/(Modelo!I12-Modelo!I10),"") -> 2.9302817 | J22: =IFERROR((Modelo!J73+Modelo!J68-Modelo!J51)/(Modelo!J12-Modelo!J10),"") -> 2.6878724 | K22: =IFERROR((Modelo!K73+Modelo!K68-Modelo!K51)/(Modelo!K12-Modelo!K10),"") -> 2.4395513
B24: 4. RETORNO AL ACCIONISTA
B26: UPA (Utilidad por Acción) | C26: $ | D26: =IFERROR(Modelo!D17/Supuestos!D63,"") -> 0.99602026 | E26: =IFERROR(Modelo!E17/Supuestos!E63,"") -> 1.753267 | F26: =IFERROR(Modelo!F17/Supuestos!F63,"") -> 1.0870293 | G26: =IFERROR(Modelo!G17/Supuestos!G63,"") -> 2.3363622 | H26: =IFERROR(Modelo!H17/Supuestos!H63,"") -> 2.4461608 | I26: =IFERROR(Modelo!I17/Supuestos!I63,"") -> 2.5784117 | J26: =IFERROR(Modelo!J17/Supuestos!J63,"") -> 2.7334629 | K26: =IFERROR(Modelo!K17/Supuestos!K63,"") -> 2.8906992
B27: Dividendos Pagados | C27: $mm | D27: =IFERROR(-Modelo!D38,"") -> 1960 | E27: =IFERROR(-Modelo!E38,"") -> 1965 | F27: =IFERROR(-Modelo!F38,"") -> 1931 | G27: =IFERROR(-Modelo!G38,"") -> 1940 | H27: =IFERROR(-Modelo!H38,"") -> 1950 | I27: =IFERROR(-Modelo!I38,"") -> 1960 | J27: =IFERROR(-Modelo!J38,"") -> 1970 | K27: =IFERROR(-Modelo!K38,"") -> 1980
B29: 5. ANÁLISIS DE RIESGO
B31: Cobertura de Intereses | C31: x | D31: =IFERROR(Modelo!D12/ABS(Modelo!D13),"") -> 2.9326819 | E31: =IFERROR(Modelo!E12/ABS(Modelo!E13),"") -> 3.9594298 | F31: =IFERROR(Modelo!F12/ABS(Modelo!F13),"") -> 0.80592105 | G31: =IFERROR(Modelo!G12/ABS(Modelo!G13),"") -> 4.9272185 | H31: =IFERROR(Modelo!H12/ABS(Modelo!H13),"") -> 5.1460353 | I31: =IFERROR(Modelo!I12/ABS(Modelo!I13),"") -> 5.4075414 | J31: =IFERROR(Modelo!J12/ABS(Modelo!J13),"") -> 5.7135737 | K31: =IFERROR(Modelo!K12/ABS(Modelo!K13),"") -> 6.0296049
B32: Cobertura de Dividendos | C32: x | D32: =IFERROR((Modelo!D30+Modelo!D33)/(-Modelo!D38),"") -> -0.46734694 | E32: =IFERROR((Modelo!E30+Modelo!E33)/(-Modelo!E38),"") -> -0.51552163 | F32: =IFERROR((Modelo!F30+Modelo!F33)/(-Modelo!F38),"") -> 1.5411704 | G32: =IFERROR((Modelo!G30+Modelo!G33)/(-Modelo!G38),"") -> 1.2766585 | H32: =IFERROR((Modelo!H30+Modelo!H33)/(-Modelo!H38),"") -> 1.3276091 | I32: =IFERROR((Modelo!I30+Modelo!I33)/(-Modelo!I38),"") -> 1.3697194 | J32: =IFERROR((Modelo!J30+Modelo!J33)/(-Modelo!J38),"") -> 1.4369863 | K32: =IFERROR((Modelo!K30+Modelo!K33)/(-Modelo!K38),"") -> 1.5000273
B33: Payout Ratio | C33: % | D33: =IFERROR(-Modelo!D38/Modelo!D17,"") -> 1.6077054 | E33: =IFERROR(-Modelo!E38/Modelo!E17,"") -> 0.92016817 | F33: =IFERROR(-Modelo!F38/Modelo!F17,"") -> 1.4865281 | G33: =IFERROR(-Modelo!G38/Modelo!G17,"") -> 0.70368704 | H33: =IFERROR(-Modelo!H38/Modelo!H17,"") -> 0.68133978 | I33: =IFERROR(-Modelo!I38/Modelo!I17,"") -> 0.65530853 | J33: =IFERROR(-Modelo!J38/Modelo!J17,"") -> 0.62669352 | K33: =IFERROR(-Modelo!K38/Modelo!K17,"") -> 0.60083806
B34: Deuda Total / Capital | C34: % | D34: =IFERROR((Modelo!D73+Modelo!D68)/(Modelo!D73+Modelo!D68+Modelo!D86),"") | E34: =IFERROR((Modelo!E73+Modelo!E68)/(Modelo!E73+Modelo!E68+Modelo!E86),"") -> 0.28848342 | F34: =IFERROR((Modelo!F73+Modelo!F68)/(Modelo!F73+Modelo!F68+Modelo!F86),"") -> 0.28717408 | G34: =IFERROR((Modelo!G73+Modelo!G68)/(Modelo!G73+Modelo!G68+Modelo!G86),"") -> 0.28157547 | H34: =IFERROR((Modelo!H73+Modelo!H68)/(Modelo!H73+Modelo!H68+Modelo!H86),"") -> 0.27589468 | I34: =IFERROR((Modelo!I73+Modelo!I68)/(Modelo!I73+Modelo!I68+Modelo!I86),"") -> 0.26987669 | J34: =IFERROR((Modelo!J73+Modelo!J68)/(Modelo!J73+Modelo!J68+Modelo!J86),"") -> 0.26347689 | K34: =IFERROR((Modelo!K73+Modelo!K68)/(Modelo!K73+Modelo!K68+Modelo!K86),"") -> 0.25674989
